Workbook

Sheet Carta Gantt
A1: Kronos AI · Carta Gantt del proyecto
A2: Proyecto de título · Ingeniería en Informática · Duoc UC · 10-08-2026 al 13-12-2026 · Scrum: tres fases académicas de 18 semanas y sprints de dos semanas
B3: Inicio de la semana 1 (kick-off) | C3: 46244 | D3: Leyenda | E3: Completado | F3: ◆ Hito cumplido
B4: Fecha de corte de esta versión | C4: 46321 | E4: En curso | F4: ◇ Hito por cumplir
B5: Actividades completadas | C5: =COUNTIF(J11:J61,"Completado")/COUNT(A11:A61) -> 0.60465116 | D5: =COUNTIF(J11:J61,"Completado")&" de "&COUNT(A11:A61) -> 26 de 43 | E5: Planificado | F5: Semana de corte
B6: Las celdas amarillas se pueden editar; las barras, los sprints y el avance se recalculan solos.
J7: Fase | K7: Fase 1 | O7: Fase 2 · Desarrollo | AA7: Fase 3
J8: Sprint | K8: =IFERROR(LOOKUP(2,1/((Sprints!$C$2:$C$6<=K$10+2)*(Sprints!$D$2:$D$6>=K$10+2)),SUBSTITUTE(Sprints!$A$2:$A$6,"Sprint ","Sp")),"") | L8: =IFERROR(LOOKUP(2,1/((Sprints!$C$2:$C$6<=L$10+2)*(Sprints!$D$2:$D$6>=L$10+2)),SUBSTITUTE(Sprints!$A$2:$A$6,"Sprint ","Sp")),"") | M8: =IFERROR(LOOKUP(2,1/((Sprints!$C$2:$C$6<=M$10+2)*(Sprints!$D$2:$D$6>=M$10+2)),SUBSTITUTE(Sprints!$A$2:$A$6,"Sprint ","Sp")),"") | N8: =IFERROR(LOOKUP(2,1/((Sprints!$C$2:$C$6<=N$10+2)*(Sprints!$D$2:$D$6>=N$10+2)),SUBSTITUTE(Sprints!$A$2:$A$6,"Sprint ","Sp")),"") | O8: =IFERROR(LOOKUP(2,1/((Sprints!$C$2:$C$6<=O$10+2)*(Sprints!$D$2:$D$6>=O$10+2)),SUBSTITUTE(Sprints!$A$2:$A$6,"Sprint ","Sp")),"") | P8: =IFERROR(LOOKUP(2,1/((Sprints!$C$2:$C$6<=P$10+2)*(Sprints!$D$2:$D$6>=P$10+2)),SUBSTITUTE(Sprints!$A$2:$A$6,"Sprint ","Sp")),"") | Q8: =IFERROR(LOOKUP(2,1/((Sprints!$C$2:$C$6<=Q$10+2)*(Sprints!$D$2:$D$6>=Q$10+2)),SUBSTITUTE(Sprints!$A$2:$A$6,"Sprint ","Sp")),"") | R8: =IFERROR(LOOKUP(2,1/((Sprints!$C$2:$C$6<=R$10+2)*(Sprints!$D$2:$D$6>=R$10+2)),SUBSTITUTE(Sprints!$A$2:$A$6,"Sprint ","Sp")),"") -> Sp1 | ... AB8: =IFERROR(LOOKUP(2,1/((Sprints!$C$2:$C$6<=AB$10+2)*(Sprints!$D$2:$D$6>=AB$10+2)),SUBSTITUTE(Sprints!$A$2:$A$6,"Sprint ","Sp")),"")
J9: Semana | K9: S1 | L9: S2 | M9: S3 | N9: S4 | O9: S5 | P9: S6 | Q9: S7 | R9: S8 | S9: S9 | T9: S10 | U9: S11 | V9: S12 | W9: S13 | X9: S14 | Y9: S15 | Z9: S16 | AA9: S17 | AB9: S18
A10: N° | B10: Actividad | C10: Fase | D10: Sprint | E10: Responsable | F10: Inicio | G10: Fin | H10: Días | I10: Tipo | J10: Estado | K10: =$C$3+7*0 -> 46244 | L10: =$C$3+7*1 -> 46251 | M10: =$C$3+7*2 -> 46258 | N10: =$C$3+7*3 -> 46265 | O10: =$C$3+7*4 -> 46272 | P10: =$C$3+7*5 -> 46279 | Q10: =$C$3+7*6 -> 46286 | R10: =$C$3+7*7 -> 46293 | S10: =$C$3+7*8 -> 46300 | T10: =$C$3+7*9 -> 46307 | U10: =$C$3+7*10 -> 46314 | V10: =$C$3+7*11 -> 46321 | W10: =$C$3+7*12 -> 46328 | X10: =$C$3+7*13 -> 46335 | Y10: =$C$3+7*14 -> 46342 | Z10: =$C$3+7*15 -> 46349 | AA10: =$C$3+7*16 -> 46356 | AB10: =$C$3+7*17 -> 46363
A11: Fase 1 · Definición del proyecto
A12: 1 | B12: Kick-off con el profesor guía | C12: Fase 1 | D12: — | E12: Equipo | F12: 46244 | G12: 46244 | H12: =G12-F12+1 -> 1 | I12: Hito | J12: Completado | K12: =IF(AND($F12<=K$10+6,$G12>=K$10),IF($I12="Hito",IF($J12="Completado","◆","◇")," "),"") -> ◆ | L12: =IF(AND($F12<=L$10+6,$G12>=L$10),IF($I12="Hito",IF($J12="Completado","◆","◇")," "),"") | M12: =IF(AND($F12<=M$10+6,$G12>=M$10),IF($I12="Hito",IF($J12="Completado","◆","◇")," "),"") | N12: =IF(AND($F12<=N$10+6,$G12>=N$10),IF($I12="Hito",IF($J12="Completado","◆","◇")," "),"") | O12: =IF(AND($F12<=O$10+6,$G12>=O$10),IF($I12="Hito",IF($J12="Completado","◆","◇")," "),"") | P12: =IF(AND($F12<=P$10+6,$G12>=P$10),IF($I12="Hito",IF($J12="Completado","◆","◇")," "),"") | Q12: =IF(AND($F12<=Q$10+6,$G12>=Q$10),IF($I12="Hito",IF($J12="Completado","◆","◇")," "),"") | R12: =IF(AND($F12<=R$10+6,$G12>=R$10),IF($I12="Hito",IF($J12="Completado","◆","◇")," "),"") | ... AB12: =IF(AND($F12<=AB$10+6,$G12>=AB$10),IF($I12="Hito",IF($J12="Completado","◆","◇")," "),"")
A13: 2 | B13: Definición del problema, objetivos, arquitectura y catálogo de 25 playbooks | C13: Fase 1 | D13: — | E13: Equipo | F13: 46244 | G13: 46257 | H13: =G13-F13+1 -> 14 | I13: Tarea | J13: Completado | K13: =IF(AND($F13<=K$10+6,$G13>=K$10),IF($I13="Hito",IF($J13="Completado","◆","◇")," "),"") | L13: =IF(AND($F13<=L$10+6,$G13>=L$10),IF($I13="Hito",IF($J13="Completado","◆","◇")," "),"") | M13: =IF(AND($F13<=M$10+6,$G13>=M$10),IF($I13="Hito",IF($J13="Completado","◆","◇")," "),"") | N13: =IF(AND($F13<=N$10+6,$G13>=N$10),IF($I13="Hito",IF($J13="Completado","◆","◇")," "),"") | O13: =IF(AND($F13<=O$10+6,$G13>=O$10),IF($I13="Hito",IF($J13="Completado","◆","◇")," "),"") | P13: =IF(AND($F13<=P$10+6,$G13>=P$10),IF($I13="Hito",IF($J13="Completado","◆","◇")," "),"") | Q13: =IF(AND($F13<=Q$10+6,$G13>=Q$10),IF($I13="Hito",IF($J13="Completado","◆","◇")," "),"") | R13: =IF(AND($F13<=R$10+6,$G13>=R$10),IF($I13="Hito",IF($J13="Completado","◆","◇")," "),"") | ... AB13: =IF(AND($F13<=AB$10+6,$G13>=AB$10),IF($I13="Hito",IF($J13="Completado","◆","◇")," "),"")
A14: 3 | B14: Primera presentación del proyecto | C14: Fase 1 | D14: — | E14: Equipo | F14: 46255 | G14: 46255 | H14: =G14-F14+1 -> 1 | I14: Hito | J14: Completado | K14: =IF(AND($F14<=K$10+6,$G14>=K$10),IF($I14="Hito",IF($J14="Completado","◆","◇")," "),"") | L14: =IF(AND($F14<=L$10+6,$G14>=L$10),IF($I14="Hito",IF($J14="Completado","◆","◇")," "),"") -> ◆ | M14: =IF(AND($F14<=M$10+6,$G14>=M$10),IF($I14="Hito",IF($J14="Completado","◆","◇")," "),"") | N14: =IF(AND($F14<=N$10+6,$G14>=N$10),IF($I14="Hito",IF($J14="Completado","◆","◇")," "),"") | O14: =IF(AND($F14<=O$10+6,$G14>=O$10),IF($I14="Hito",IF($J14="Completado","◆","◇")," "),"") | P14: =IF(AND($F14<=P$10+6,$G14>=P$10),IF($I14="Hito",IF($J14="Completado","◆","◇")," "),"") | Q14: =IF(AND($F14<=Q$10+6,$G14>=Q$10),IF($I14="Hito",IF($J14="Completado","◆","◇")," "),"") | R14: =IF(AND($F14<=R$10+6,$G14>=R$10),IF($I14="Hito",IF($J14="Completado","◆","◇")," "),"") | ... AB14: =IF(AND($F14<=AB$10+6,$G14>=AB$10),IF($I14="Hito",IF($J14="Completado","◆","◇")," "),"")
A15: 4 | B15: Guía de definición, Formativa Fase 1, autoevaluaciones y diarios de reflexión | C15: Fase 1 | D15: — | E15: Equipo | F15: 46265 | G15: 46268 | H15: =G15-F15+1 -> 4 | I15: Tarea | J15: Completado | K15: =IF(AND($F15<=K$10+6,$G15>=K$10),IF($I15="Hito",IF($J15="Completado","◆","◇")," "),"") | L15: =IF(AND($F15<=L$10+6,$G15>=L$10),IF($I15="Hito",IF($J15="Completado","◆","◇")," "),"") | M15: =IF(AND($F15<=M$10+6,$G15>=M$10),IF($I15="Hito",IF($J15="Completado","◆","◇")," "),"") | N15: =IF(AND($F15<=N$10+6,$G15>=N$10),IF($I15="Hito",IF($J15="Completado","◆","◇")," "),"") | O15: =IF(AND($F15<=O$10+6,$G15>=O$10),IF($I15="Hito",IF($J15="Completado","◆","◇")," "),"") | P15: =IF(AND($F15<=P$10+6,$G15>=P$10),IF($I15="Hito",IF($J15="Completado","◆","◇")," "),"") | Q15: =IF(AND($F15<=Q$10+6,$G15>=Q$10),IF($I15="Hito",IF($J15="Completado","◆","◇")," "),"") | R15: =IF(AND($F15<=R$10+6,$G15>=R$10),IF($I15="Hito",IF($J15="Completado","◆","◇")," "),"") | ... AB15: =IF(AND($F15<=AB$10+6,$G15>=AB$10),IF($I15="Hito",IF($J15="Completado","◆","◇")," "),"")
A16: 5 | B16: Presentación de la Fase 1 | C16: Fase 1 | D16: — | E16: Equipo | F16: 46268 | G16: 46268 | H16: =G16-F16+1 -> 1 | I16: Hito | J16: Completado | K16: =IF(AND($F16<=K$10+6,$G16>=K$10),IF($I16="Hito",IF($J16="Completado","◆","◇")," "),"") | L16: =IF(AND($F16<=L$10+6,$G16>=L$10),IF($I16="Hito",IF($J16="Completado","◆","◇")," "),"") | M16: =IF(AND($F16<=M$10+6,$G16>=M$10),IF($I16="Hito",IF($J16="Completado","◆","◇")," "),"") | N16: =IF(AND($F16<=N$10+6,$G16>=N$10),IF($I16="Hito",IF($J16="Completado","◆","◇")," "),"") -> ◆ | O16: =IF(AND($F16<=O$10+6,$G16>=O$10),IF($I16="Hito",IF($J16="Completado","◆","◇")," "),"") | P16: =IF(AND($F16<=P$10+6,$G16>=P$10),IF($I16="Hito",IF($J16="Completado","◆","◇")," "),"") | Q16: =IF(AND($F16<=Q$10+6,$G16>=Q$10),IF($I16="Hito",IF($J16="Completado","◆","◇")," "),"") | R16: =IF(AND($F16<=R$10+6,$G16>=R$10),IF($I16="Hito",IF($J16="Completado","◆","◇")," "),"") | ... AB16: =IF(AND($F16<=AB$10+6,$G16>=AB$10),IF($I16="Hito",IF($J16="Completado","◆","◇")," "),"")
A17: 6 | B17: Prototipo en laboratorio local, etapas 1 a 4 (anfitrión, datos, monitoreo e IA) | C17: Fase 1 a Fase 2 | D17: — | E17: Nicolás, Rodrigo y Patricio | F17: 46251 | G17: 46289 | H17: =G17-F17+1 -> 39 | I17: Tarea | J17: Completado | K17: =IF(AND($F17<=K$10+6,$G17>=K$10),IF($I17="Hito",IF($J17="Completado","◆","◇")," "),"") | L17: =IF(AND($F17<=L$10+6,$G17>=L$10),IF($I17="Hito",IF($J17="Completado","◆","◇")," "),"") | M17: =IF(AND($F17<=M$10+6,$G17>=M$10),IF($I17="Hito",IF($J17="Completado","◆","◇")," "),"") | N17: =IF(AND($F17<=N$10+6,$G17>=N$10),IF($I17="Hito",IF($J17="Completado","◆","◇")," "),"") | O17: =IF(AND($F17<=O$10+6,$G17>=O$10),IF($I17="Hito",IF($J17="Completado","◆","◇")," "),"") | P17: =IF(AND($F17<=P$10+6,$G17>=P$10),IF($I17="Hito",IF($J17="Completado","◆","◇")," "),"") | Q17: =IF(AND($F17<=Q$10+6,$G17>=Q$10),IF($I17="Hito",IF($J17="Completado","◆","◇")," "),"") | R17: =IF(AND($F17<=R$10+6,$G17>=R$10),IF($I17="Hito",IF($J17="Completado","◆","◇")," "),"") | ... AB17: =IF(AND($F17<=AB$10+6,$G17>=AB$10),IF($I17="Hito",IF($J17="Completado","◆","◇")," "),"")
A18: Fase 2 · Sprint 1 · Infraestructura en la nube
A19: 7 | B19: Replanteamiento como servicio en la nube | C19: Fase 2 | D19: Sprint 1 | E19: Equipo | F19: 46290 | G19: 46290 | H19: =G19-F19+1 -> 1 | I19: Hito | J19: Completado | K19: =IF(AND($F19<=K$10+6,$G19>=K$10),IF($I19="Hito",IF($J19="Completado","◆","◇")," "),"") | L19: =IF(AND($F19<=L$10+6,$G19>=L$10),IF($I19="Hito",IF($J19="Completado","◆","◇")," "),"") | M19: =IF(AND($F19<=M$10+6,$G19>=M$10),IF($I19="Hito",IF($J19="Completado","◆","◇")," "),"") | N19: =IF(AND($F19<=N$10+6,$G19>=N$10),IF($I19="Hito",IF($J19="Completado","◆","◇")," "),"") | O19: =IF(AND($F19<=O$10+6,$G19>=O$10),IF($I19="Hito",IF($J19="Completado","◆","◇")," "),"") | P19: =IF(AND($F19<=P$10+6,$G19>=P$10),IF($I19="Hito",IF($J19="Completado","◆","◇")," "),"") | Q19: =IF(AND($F19<=Q$10+6,$G19>=Q$10),IF($I19="Hito",IF($J19="Completado","◆","◇")," "),"") -> ◆ | R19: =IF(AND($F19<=R$10+6,$G19>=R$10),IF($I19="Hito",IF($J19="Completado","◆","◇")," "),"") | ... AB19: =IF(AND($F19<=AB$10+6,$G19>=AB$10),IF($I19="Hito",IF($J19="Completado","◆","◇")," "),"")
A20: 8 | B20: Servidor SOAR-CORE-01: Contabo, NetBird, Docker y Wazuh 4.14.8 | C20: Fase 2 | D20: Sprint 1 | E20: Nicolás | F20: 46290 | G20: 46300 | H20: =G20-F20+1 -> 11 | I20: Tarea | J20: Completado | K20: =IF(AND($F20<=K$10+6,$G20>=K$10),IF($I20="Hito",IF($J20="Completado","◆","◇")," "),"") | L20: =IF(AND($F20<=L$10+6,$G20>=L$10),IF($I20="Hito",IF($J20="Completado","◆","◇")," "),"") | M20: =IF(AND($F20<=M$10+6,$G20>=M$10),IF($I20="Hito",IF($J20="Completado","◆","◇")," "),"") | N20: =IF(AND($F20<=N$10+6,$G20>=N$10),IF($I20="Hito",IF($J20="Completado","◆","◇")," "),"") | O20: =IF(AND($F20<=O$10+6,$G20>=O$10),IF($I20="Hito",IF($J20="Completado","◆","◇")," "),"") | P20: =IF(AND($F20<=P$10+6,$G20>=P$10),IF($I20="Hito",IF($J20="Completado","◆","◇")," "),"") | Q20: =IF(AND($F20<=Q$10+6,$G20>=Q$10),IF($I20="Hito",IF($J20="Completado","◆","◇")," "),"") | R20: =IF(AND($F20<=R$10+6,$G20>=R$10),IF($I20="Hito",IF($J20="Completado","◆","◇")," "),"") | ... AB20: =IF(AND($F20<=AB$10+6,$G20>=AB$10),IF($I20="Hito",IF($J20="Completado","◆","◇")," "),"")
A21: Fase 2 · Sprint 2 · Núcleo de decisión
A22: 9 | B22: Repositorio nuevo e integración continua (gitleaks, ruff y R1) | C22: Fase 2 | D22: Sprint 2 | E22: Rodrigo | F22: 46301 | G22: 46301 | H22: =G22-F22+1 -> 1 | I22: Tarea | J22: Completado | K22: =IF(AND($F22<=K$10+6,$G22>=K$10),IF($I22="Hito",IF($J22="Completado","◆","◇")," "),"") | L22: =IF(AND($F22<=L$10+6,$G22>=L$10),IF($I22="Hito",IF($J22="Completado","◆","◇")," "),"") | M22: =IF(AND($F22<=M$10+6,$G22>=M$10),IF($I22="Hito",IF($J22="Completado","◆","◇")," "),"") | N22: =IF(AND($F22<=N$10+6,$G22>=N$10),IF($I22="Hito",IF($J22="Completado","◆","◇")," "),"") | O22: =IF(AND($F22<=O$10+6,$G22>=O$10),IF($I22="Hito",IF($J22="Completado","◆","◇")," "),"") | P22: =IF(AND($F22<=P$10+6,$G22>=P$10),IF($I22="Hito",IF($J22="Completado","◆","◇")," "),"") | Q22: =IF(AND($F22<=Q$10+6,$G22>=Q$10),IF($I22="Hito",IF($J22="Completado","◆","◇")," "),"") | R22: =IF(AND($F22<=R$10+6,$G22>=R$10),IF($I22="Hito",IF($J22="Completado","◆","◇")," "),"") | ... AB22: =IF(AND($F22<=AB$10+6,$G22>=AB$10),IF($I22="Hito",IF($J22="Completado","◆","◇")," "),"")
A23: 10 | B23: Modelo de datos y auditoría con cadena de hash; respaldo cifrado y restauración probada | C23: Fase 2 | D23: Sprint 2 | E23: Rodrigo | F23: 46301 | G23: 46310 | H23: =G23-F23+1 -> 10 | I23: Tarea | J23: Completado | K23: =IF(AND($F23<=K$10+6,$G23>=K$10),IF($I23="Hito",IF($J23="Completado","◆","◇")," "),"") | L23: =IF(AND($F23<=L$10+6,$G23>=L$10),IF($I23="Hito",IF($J23="Completado","◆","◇")," "),"") | M23: =IF(AND($F23<=M$10+6,$G23>=M$10),IF($I23="Hito",IF($J23="Completado","◆","◇")," "),"") | N23: =IF(AND($F23<=N$10+6,$G23>=N$10),IF($I23="Hito",IF($J23="Completado","◆","◇")," "),"") | O23: =IF(AND($F23<=O$10+6,$G23>=O$10),IF($I23="Hito",IF($J23="Completado","◆","◇")," "),"") | P23: =IF(AND($F23<=P$10+6,$G23>=P$10),IF($I23="Hito",IF($J23="Completado","◆","◇")," "),"") | Q23: =IF(AND($F23<=Q$10+6,$G23>=Q$10),IF($I23="Hito",IF($J23="Completado","◆","◇")," "),"") | R23: =IF(AND($F23<=R$10+6,$G23>=R$10),IF($I23="Hito",IF($J23="Completado","◆","◇")," "),"") | ... AB23: =IF(AND($F23<=AB$10+6,$G23>=AB$10),IF($I23="Hito",IF($J23="Completado","◆","◇")," "),"")
A24: 11 | B24: Clasificador con IA local (qwen2.5:7b): prompts en dos pasos y mediciones con 150 casos | C24: Fase 2 | D24: Sprint 2 | E24: Patricio | F24: 46301 | G24: 46310 | H24: =G24-F24+1 -> 10 | I24: Tarea | J24: Completado | K24: =IF(AND($F24<=K$10+6,$G24>=K$10),IF($I24="Hito",IF($J24="Completado","◆","◇")," "),"") | L24: =IF(AND($F24<=L$10+6,$G24>=L$10),IF($I24="Hito",IF($J24="Completado","◆","◇")," "),"") | M24: =IF(AND($F24<=M$10+6,$G24>=M$10),IF($I24="Hito",IF($J24="Completado","◆","◇")," "),"") | N24: =IF(AND($F24<=N$10+6,$G24>=N$10),IF($I24="Hito",IF($J24="Completado","◆","◇")," "),"") | O24: =IF(AND($F24<=O$10+6,$G24>=O$10),IF($I24="Hito",IF($J24="Completado","◆","◇")," "),"") | P24: =IF(AND($F24<=P$10+6,$G24>=P$10),IF($I24="Hito",IF($J24="Completado","◆","◇")," "),"") | Q24: =IF(AND($F24<=Q$10+6,$G24>=Q$10),IF($I24="Hito",IF($J24="Completado","◆","◇")," "),"") | R24: =IF(AND($F24<=R$10+6,$G24>=R$10),IF($I24="Hito",IF($J24="Completado","◆","◇")," "),"") | ... AB24: =IF(AND($F24<=AB$10+6,$G24>=AB$10),IF($I24="Hito",IF($J24="Completado","◆","◇")," "),"")
A25: 12 | B25: Detección: Wazuh y 15 reglas de sobre | C25: Fase 2 | D25: Sprint 2 | E25: Nicolás | F25: 46307 | G25: 46309 | H25: =G25-F25+1 -> 3 | I25: Tarea | J25: Completado | K25: =IF(AND($F25<=K$10+6,$G25>=K$10),IF($I25="Hito",IF($J25="Completado","◆","◇")," "),"") | L25: =IF(AND($F25<=L$10+6,$G25>=L$10),IF($I25="Hito",IF($J25="Completado","◆","◇")," "),"") | M25: =IF(AND($F25<=M$10+6,$G25>=M$10),IF($I25="Hito",IF($J25="Completado","◆","◇")," "),"") | N25: =IF(AND($F25<=N$10+6,$G25>=N$10),IF($I25="Hito",IF($J25="Completado","◆","◇")," "),"") | O25: =IF(AND($F25<=O$10+6,$G25>=O$10),IF($I25="Hito",IF($J25="Completado","◆","◇")," "),"") | P25: =IF(AND($F25<=P$10+6,$G25>=P$10),IF($I25="Hito",IF($J25="Completado","◆","◇")," "),"") | Q25: =IF(AND($F25<=Q$10+6,$G25>=Q$10),IF($I25="Hito",IF($J25="Completado","◆","◇")," "),"") | R25: =IF(AND($F25<=R$10+6,$G25>=R$10),IF($I25="Hito",IF($J25="Completado","◆","◇")," "),"") | ... AB25: =IF(AND($F25<=AB$10+6,$G25>=AB$10),IF($I25="Hito",IF($J25="Completado","◆","◇")," "),"")
A26: 13 | B26: Servicio VALIDATE: chequeos, configuración, lectura de alertas y servicio | C26: Fase 2 | D26: Sprint 2 | E26: Patricio | F26: 46309 | G26: 46311 | H26: =G26-F26+1 -> 3 | I26: Tarea | J26: Completado | K26: =IF(AND($F26<=K$10+6,$G26>=K$10),IF($I26="Hito",IF($J26="Completado","◆","◇")," "),"") | L26: =IF(AND($F26<=L$10+6,$G26>=L$10),IF($I26="Hito",IF($J26="Completado","◆","◇")," "),"") | M26: =IF(AND($F26<=M$10+6,$G26>=M$10),IF($I26="Hito",IF($J26="Completado","◆","◇")," "),"") | N26: =IF(AND($F26<=N$10+6,$G26>=N$10),IF($I26="Hito",IF($J26="Completado","◆","◇")," "),"") | O26: =IF(AND($F26<=O$10+6,$G26>=O$10),IF($I26="Hito",IF($J26="Completado","◆","◇")," "),"") | P26: =IF(AND($F26<=P$10+6,$G26>=P$10),IF($I26="Hito",IF($J26="Completado","◆","◇")," "),"") | Q26: =IF(AND($F26<=Q$10+6,$G26>=Q$10),IF($I26="Hito",IF($J26="Completado","◆","◇")," "),"") | R26: =IF(AND($F26<=R$10+6,$G26>=R$10),IF($I26="Hito",IF($J26="Completado","◆","◇")," "),"") | ... AB26: =IF(AND($F26<=AB$10+6,$G26>=AB$10),IF($I26="Hito",IF($J26="Completado","◆","◇")," "),"")
A27: 14 | B27: Servicios EXECUTE y NOTIFY, y despliegue con Docker | C27: Fase 2 | D27: Sprint 2 | E27: Rodrigo | F27: 46310 | G27: 46310 | H27: =G27-F27+1 -> 1 | I27: Tarea | J27: Completado | K27: =IF(AND($F27<=K$10+6,$G27>=K$10),IF($I27="Hito",IF($J27="Completado","◆","◇")," "),"") | L27: =IF(AND($F27<=L$10+6,$G27>=L$10),IF($I27="Hito",IF($J27="Completado","◆","◇")," "),"") | M27: =IF(AND($F27<=M$10+6,$G27>=M$10),IF($I27="Hito",IF($J27="Completado","◆","◇")," "),"") | N27: =IF(AND($F27<=N$10+6,$G27>=N$10),IF($I27="Hito",IF($J27="Completado","◆","◇")," "),"") | O27: =IF(AND($F27<=O$10+6,$G27>=O$10),IF($I27="Hito",IF($J27="Completado","◆","◇")," "),"") | P27: =IF(AND($F27<=P$10+6,$G27>=P$10),IF($I27="Hito",IF($J27="Completado","◆","◇")," "),"") | Q27: =IF(AND($F27<=Q$10+6,$G27>=Q$10),IF($I27="Hito",IF($J27="Completado","◆","◇")," "),"") | R27: =IF(AND($F27<=R$10+6,$G27>=R$10),IF($I27="Hito",IF($J27="Completado","◆","◇")," "),"") | ... AB27: =IF(AND($F27<=AB$10+6,$G27>=AB$10),IF($I27="Hito",IF($J27="Completado","◆","◇")," "),"")
A28: 15 | B28: Consola web para revisar tickets y aprobaciones | C28: Fase 2 | D28: Sprint 2 | E28: Rodrigo | F28: 46310 | G28: 46311 | H28: =G28-F28+1 -> 2 | I28: Tarea | J28: Completado | K28: =IF(AND($F28<=K$10+6,$G28>=K$10),IF($I28="Hito",IF($J28="Completado","◆","◇")," "),"") | L28: =IF(AND($F28<=L$10+6,$G28>=L$10),IF($I28="Hito",IF($J28="Completado","◆","◇")," "),"") | M28: =IF(AND($F28<=M$10+6,$G28>=M$10),IF($I28="Hito",IF($J28="Completado","◆","◇")," "),"") | N28: =IF(AND($F28<=N$10+6,$G28>=N$10),IF($I28="Hito",IF($J28="Completado","◆","◇")," "),"") | O28: =IF(AND($F28<=O$10+6,$G28>=O$10),IF($I28="Hito",IF($J28="Completado","◆","◇")," "),"") | P28: =IF(AND($F28<=P$10+6,$G28>=P$10),IF($I28="Hito",IF($J28="Completado","◆","◇")," "),"") | Q28: =IF(AND($F28<=Q$10+6,$G28>=Q$10),IF($I28="Hito",IF($J28="Completado","◆","◇")," "),"") | R28: =IF(AND($F28<=R$10+6,$G28>=R$10),IF($I28="Hito",IF($J28="Completado","◆","◇")," "),"") | ... AB28: =IF(AND($F28<=AB$10+6,$G28>=AB$10),IF($I28="Hito",IF($J28="Completado","◆","◇")," "),"")
A29: 16 | B29: Documentos del proyecto: entrega de los 31 documentos | C29: Fase 2 | D29: Sprint 2 | E29: Equipo | F29: 46307 | G29: 46311 | H29: =G29-F29+1 -> 5 | I29: Tarea | J29: Completado | K29: =IF(AND($F29<=K$10+6,$G29>=K$10),IF($I29="Hito",IF($J29="Completado","◆","◇")," "),"") | L29: =IF(AND($F29<=L$10+6,$G29>=L$10),IF($I29="Hito",IF($J29="Completado","◆","◇")," "),"") | M29: =IF(AND($F29<=M$10+6,$G29>=M$10),IF($I29="Hito",IF($J29="Completado","◆","◇")," "),"") | N29: =IF(AND($F29<=N$10+6,$G29>=N$10),IF($I29="Hito",IF($J29="Completado","◆","◇")," "),"") | O29: =IF(AND($F29<=O$10+6,$G29>=O$10),IF($I29="Hito",IF($J29="Completado","◆","◇")," "),"") | P29: =IF(AND($F29<=P$10+6,$G29>=P$10),IF($I29="Hito",IF($J29="Completado","◆","◇")," "),"") | Q29: =IF(AND($F29<=Q$10+6,$G29>=Q$10),IF($I29="Hito",IF($J29="Completado","◆","◇")," "),"") | R29: =IF(AND($F29<=R$10+6,$G29>=R$10),IF($I29="Hito",IF($J29="Completado","◆","◇")," "),"") | ... AB29: =IF(AND($F29<=AB$10+6,$G29>=AB$10),IF($I29="Hito",IF($J29="Completado","◆","◇")," "),"")
A30: 17 | B30: Entrega de documentos | C30: Fase 2 | D30: Sprint 2 | E30: Equipo | F30: 46311 | G30: 46311 | H30: =G30-F30+1 -> 1 | I30: Hito | J30: Completado | K30: =IF(AND($F30<=K$10+6,$G30>=K$10),IF($I30="Hito",IF($J30="Completado","◆","◇")," "),"") | L30: =IF(AND($F30<=L$10+6,$G30>=L$10),IF($I30="Hito",IF($J30="Completado","◆","◇")," "),"") | M30: =IF(AND($F30<=M$10+6,$G30>=M$10),IF($I30="Hito",IF($J30="Completado","◆","◇")," "),"") | N30: =IF(AND($F30<=N$10+6,$G30>=N$10),IF($I30="Hito",IF($J30="Completado","◆","◇")," "),"") | O30: =IF(AND($F30<=O$10+6,$G30>=O$10),IF($I30="Hito",IF($J30="Completado","◆","◇")," "),"") | P30: =IF(AND($F30<=P$10+6,$G30>=P$10),IF($I30="Hito",IF($J30="Completado","◆","◇")," "),"") | Q30: =IF(AND($F30<=Q$10+6,$G30>=Q$10),IF($I30="Hito",IF($J30="Completado","◆","◇")," "),"") | R30: =IF(AND($F30<=R$10+6,$G30>=R$10),IF($I30="Hito",IF($J30="Completado","◆","◇")," "),"") | ... AB30: =IF(AND($F30<=AB$10+6,$G30>=AB$10),IF($I30="Hito",IF($J30="Completado","◆","◇")," "),"")
A31: 18 | B31: Guía de desarrollo, diario de reflexión, Formativa de avance y autoevaluaciones de la Fase 2 | C31: Fase 2 | D31: Sprint 2 | E31: Equipo | F31: 46307 | G31: 46314 | H31: =G31-F31+1 -> 8 | I31: Tarea | J31: Completado | K31: =IF(AND($F31<=K$10+6,$G31>=K$10),IF($I31="Hito",IF($J31="Completado","◆","◇")," "),"") | L31: =IF(AND($F31<=L$10+6,$G31>=L$10),IF($I31="Hito",IF($J31="Completado","◆","◇")," "),"") | M31: =IF(AND($F31<=M$10+6,$G31>=M$10),IF($I31="Hito",IF($J31="Completado","◆","◇")," "),"") | N31: =IF(AND($F31<=N$10+6,$G31>=N$10),IF($I31="Hito",IF($J31="Completado","◆","◇")," "),"") | O31: =IF(AND($F31<=O$10+6,$G31>=O$10),IF($I31="Hito",IF($J31="Completado","◆","◇")," "),"") | P31: =IF(AND($F31<=P$10+6,$G31>=P$10),IF($I31="Hito",IF($J31="Completado","◆","◇")," "),"") | Q31: =IF(AND($F31<=Q$10+6,$G31>=Q$10),IF($I31="Hito",IF($J31="Completado","◆","◇")," "),"") | R31: =IF(AND($F31<=R$10+6,$G31>=R$10),IF($I31="Hito",IF($J31="Completado","◆","◇")," "),"") | ... AB31: =IF(AND($F31<=AB$10+6,$G31>=AB$10),IF($I31="Hito",IF($J31="Completado","◆","◇")," "),"")
A32: 19 | B32: Laboratorio de la PyME simulada: EP-SRV-01 y EP-WKS-01 con agentes Wazuh | C32: Fase 2 | D32: Sprint 2 | E32: Nicolás | F32: 46309 | G32: 46316 | H32: =G32-F32+1 -> 8 | I32: Tarea | J32: Completado | K32: =IF(AND($F32<=K$10+6,$G32>=K$10),IF($I32="Hito",IF($J32="Completado","◆","◇")," "),"") | L32: =IF(AND($F32<=L$10+6,$G32>=L$10),IF($I32="Hito",IF($J32="Completado","◆","◇")," "),"") | M32: =IF(AND($F32<=M$10+6,$G32>=M$10),IF($I32="Hito",IF($J32="Completado","◆","◇")," "),"") | N32: =IF(AND($F32<=N$10+6,$G32>=N$10),IF($I32="Hito",IF($J32="Completado","◆","◇")," "),"") | O32: =IF(AND($F32<=O$10+6,$G32>=O$10),IF($I32="Hito",IF($J32="Completado","◆","◇")," "),"") | P32: =IF(AND($F32<=P$10+6,$G32>=P$10),IF($I32="Hito",IF($J32="Completado","◆","◇")," "),"") | Q32: =IF(AND($F32<=Q$10+6,$G32>=Q$10),IF($I32="Hito",IF($J32="Completado","◆","◇")," "),"") | R32: =IF(AND($F32<=R$10+6,$G32>=R$10),IF($I32="Hito",IF($J32="Completado","◆","◇")," "),"") | ... AB32: =IF(AND($F32<=AB$10+6,$G32>=AB$10),IF($I32="Hito",IF($J32="Completado","◆","◇")," "),"")
A33: Fase 2 · Sprint 3 · Respuesta, niveles y versión 1.0
A34: 20 | B34: Primer ticket de punta a punta con alertas reales | C34: Fase 2 | D34: Sprint 3 | E34: Equipo | F34: 46315 | G34: 46315 | H34: =G34-F34+1 -> 1 | I34: Hito | J34: Completado | K34: =IF(AND($F34<=K$10+6,$G34>=K$10),IF($I34="Hito",IF($J34="Completado","◆","◇")," "),"") | L34: =IF(AND($F34<=L$10+6,$G34>=L$10),IF($I34="Hito",IF($J34="Completado","◆","◇")," "),"") | M34: =IF(AND($F34<=M$10+6,$G34>=M$10),IF($I34="Hito",IF($J34="Completado","◆","◇")," "),"") | N34: =IF(AND($F34<=N$10+6,$G34>=N$10),IF($I34="Hito",IF($J34="Completado","◆","◇")," "),"") | O34: =IF(AND($F34<=O$10+6,$G34>=O$10),IF($I34="Hito",IF($J34="Completado","◆","◇")," "),"") | P34: =IF(AND($F34<=P$10+6,$G34>=P$10),IF($I34="Hito",IF($J34="Completado","◆","◇")," "),"") | Q34: =IF(AND($F34<=Q$10+6,$G34>=Q$10),IF($I34="Hito",IF($J34="Completado","◆","◇")," "),"") | R34: =IF(AND($F34<=R$10+6,$G34>=R$10),IF($I34="Hito",IF($J34="Completado","◆","◇")," "),"") | ... AB34: =IF(AND($F34<=AB$10+6,$G34>=AB$10),IF($I34="Hito",IF($J34="Completado","◆","◇")," "),"")
A35: 21 | B35: Respuesta activa: bloqueo de IP en Linux y Windows, reversión a los 60 minutos | C35: Fase 2 | D35: Sprint 3 | E35: Nicolás y Rodrigo | F35: 46315 | G35: 46316 | H35: =G35-F35+1 -> 2 | I35: Tarea | J35: Completado | K35: =IF(AND($F35<=K$10+6,$G35>=K$10),IF($I35="Hito",IF($J35="Completado","◆","◇")," "),"") | L35: =IF(AND($F35<=L$10+6,$G35>=L$10),IF($I35="Hito",IF($J35="Completado","◆","◇")," "),"") | M35: =IF(AND($F35<=M$10+6,$G35>=M$10),IF($I35="Hito",IF($J35="Completado","◆","◇")," "),"") | N35: =IF(AND($F35<=N$10+6,$G35>=N$10),IF($I35="Hito",IF($J35="Completado","◆","◇")," "),"") | O35: =IF(AND($F35<=O$10+6,$G35>=O$10),IF($I35="Hito",IF($J35="Completado","◆","◇")," "),"") | P35: =IF(AND($F35<=P$10+6,$G35>=P$10),IF($I35="Hito",IF($J35="Completado","◆","◇")," "),"") | Q35: =IF(AND($F35<=Q$10+6,$G35>=Q$10),IF($I35="Hito",IF($J35="Completado","◆","◇")," "),"") | R35: =IF(AND($F35<=R$10+6,$G35>=R$10),IF($I35="Hito",IF($J35="Completado","◆","◇")," "),"") | ... AB35: =IF(AND($F35<=AB$10+6,$G35>=AB$10),IF($I35="Hito",IF($J35="Completado","◆","◇")," "),"")
A36: 22 | B36: Retención de alertas, tickets huérfanos y mejoras de VALIDATE | C36: Fase 2 | D36: Sprint 3 | E36: Rodrigo y Patricio | F36: 46315 | G36: 46316 | H36: =G36-F36+1 -> 2 | I36: Tarea | J36: Completado | K36: =IF(AND($F36<=K$10+6,$G36>=K$10),IF($I36="Hito",IF($J36="Completado","◆","◇")," "),"") | L36: =IF(AND($F36<=L$10+6,$G36>=L$10),IF($I36="Hito",IF($J36="Completado","◆","◇")," "),"") | M36: =IF(AND($F36<=M$10+6,$G36>=M$10),IF($I36="Hito",IF($J36="Completado","◆","◇")," "),"") | N36: =IF(AND($F36<=N$10+6,$G36>=N$10),IF($I36="Hito",IF($J36="Completado","◆","◇")," "),"") | O36: =IF(AND($F36<=O$10+6,$G36>=O$10),IF($I36="Hito",IF($J36="Completado","◆","◇")," "),"") | P36: =IF(AND($F36<=P$10+6,$G36>=P$10),IF($I36="Hito",IF($J36="Completado","◆","◇")," "),"") | Q36: =IF(AND($F36<=Q$10+6,$G36>=Q$10),IF($I36="Hito",IF($J36="Completado","◆","◇")," "),"") | R36: =IF(AND($F36<=R$10+6,$G36>=R$10),IF($I36="Hito",IF($J36="Completado","◆","◇")," "),"") | ... AB36: =IF(AND($F36<=AB$10+6,$G36>=AB$10),IF($I36="Hito",IF($J36="Completado","◆","◇")," "),"")
A37: 23 | B37: Avisos por Telegram con verificación en dos pasos | C37: Fase 2 | D37: Sprint 3 | E37: Rodrigo | F37: 46316 | G37: 46316 | H37: =G37-F37+1 -> 1 | I37: Tarea | J37: Completado | K37: =IF(AND($F37<=K$10+6,$G37>=K$10),IF($I37="Hito",IF($J37="Completado","◆","◇")," "),"") | L37: =IF(AND($F37<=L$10+6,$G37>=L$10),IF($I37="Hito",IF($J37="Completado","◆","◇")," "),"") | M37: =IF(AND($F37<=M$10+6,$G37>=M$10),IF($I37="Hito",IF($J37="Completado","◆","◇")," "),"") | N37: =IF(AND($F37<=N$10+6,$G37>=N$10),IF($I37="Hito",IF($J37="Completado","◆","◇")," "),"") | O37: =IF(AND($F37<=O$10+6,$G37>=O$10),IF($I37="Hito",IF($J37="Completado","◆","◇")," "),"") | P37: =IF(AND($F37<=P$10+6,$G37>=P$10),IF($I37="Hito",IF($J37="Completado","◆","◇")," "),"") | Q37: =IF(AND($F37<=Q$10+6,$G37>=Q$10),IF($I37="Hito",IF($J37="Completado","◆","◇")," "),"") | R37: =IF(AND($F37<=R$10+6,$G37>=R$10),IF($I37="Hito",IF($J37="Completado","◆","◇")," "),"") | ... AB37: =IF(AND($F37<=AB$10+6,$G37>=AB$10),IF($I37="Hito",IF($J37="Completado","◆","◇")," "),"")
A38: 24 | B38: Punto de encuentro 1 (decisiones D-44 a D-56) | C38: Fase 2 | D38: Sprint 3 | E38: Equipo | F38: 46316 | G38: 46316 | H38: =G38-F38+1 -> 1 | I38: Hito | J38: Completado | K38: =IF(AND($F38<=K$10+6,$G38>=K$10),IF($I38="Hito",IF($J38="Completado","◆","◇")," "),"") | L38: =IF(AND($F38<=L$10+6,$G38>=L$10),IF($I38="Hito",IF($J38="Completado","◆","◇")," "),"") | M38: =IF(AND($F38<=M$10+6,$G38>=M$10),IF($I38="Hito",IF($J38="Completado","◆","◇")," "),"") | N38: =IF(AND($F38<=N$10+6,$G38>=N$10),IF($I38="Hito",IF($J38="Completado","◆","◇")," "),"") | O38: =IF(AND($F38<=O$10+6,$G38>=O$10),IF($I38="Hito",IF($J38="Completado","◆","◇")," "),"") | P38: =IF(AND($F38<=P$10+6,$G38>=P$10),IF($I38="Hito",IF($J38="Completado","◆","◇")," "),"") | Q38: =IF(AND($F38<=Q$10+6,$G38>=Q$10),IF($I38="Hito",IF($J38="Completado","◆","◇")," "),"") | R38: =IF(AND($F38<=R$10+6,$G38>=R$10),IF($I38="Hito",IF($J38="Completado","◆","◇")," "),"") | ... AB38: =IF(AND($F38<=AB$10+6,$G38>=AB$10),IF($I38="Hito",IF($J38="Completado","◆","◇")," "),"")
A39: 25 | B39: Replanteamiento para PyMEs y arranque de la semana de cierre | C39: Fase 2 | D39: Sprint 3 | E39: Equipo | F39: 46321 | G39: 46321 | H39: =G39-F39+1 -> 1 | I39: Hito | J39: Completado | K39: =IF(AND($F39<=K$10+6,$G39>=K$10),IF($I39="Hito",IF($J39="Completado","◆","◇")," "),"") | L39: =IF(AND($F39<=L$10+6,$G39>=L$10),IF($I39="Hito",IF($J39="Completado","◆","◇")," "),"") | M39: =IF(AND($F39<=M$10+6,$G39>=M$10),IF($I39="Hito",IF($J39="Completado","◆","◇")," "),"") | N39: =IF(AND($F39<=N$10+6,$G39>=N$10),IF($I39="Hito",IF($J39="Completado","◆","◇")," "),"") | O39: =IF(AND($F39<=O$10+6,$G39>=O$10),IF($I39="Hito",IF($J39="Completado","◆","◇")," "),"") | P39: =IF(AND($F39<=P$10+6,$G39>=P$10),IF($I39="Hito",IF($J39="Completado","◆","◇")," "),"") | Q39: =IF(AND($F39<=Q$10+6,$G39>=Q$10),IF($I39="Hito",IF($J39="Completado","◆","◇")," "),"") | R39: =IF(AND($F39<=R$10+6,$G39>=R$10),IF($I39="Hito",IF($J39="Completado","◆","◇")," "),"") | ... AB39: =IF(AND($F39<=AB$10+6,$G39>=AB$10),IF($I39="Hito",IF($J39="Completado","◆","◇")," "),"")
A40: 26 | B40: Repositorio ordenado por fases, README, diagramas, avisos claros y catálogo 1.0 | C40: Fase 2 | D40: Sprint 3 | E40: Equipo | F40: 46321 | G40: 46321 | H40: =G40-F40+1 -> 1 | I40: Tarea | J40: Completado | K40: =IF(AND($F40<=K$10+6,$G40>=K$10),IF($I40="Hito",IF($J40="Completado","◆","◇")," "),"") | L40: =IF(AND($F40<=L$10+6,$G40>=L$10),IF($I40="Hito",IF($J40="Completado","◆","◇")," "),"") | M40: =IF(AND($F40<=M$10+6,$G40>=M$10),IF($I40="Hito",IF($J40="Completado","◆","◇")," "),"") | N40: =IF(AND($F40<=N$10+6,$G40>=N$10),IF($I40="Hito",IF($J40="Completado","◆","◇")," "),"") | O40: =IF(AND($F40<=O$10+6,$G40>=O$10),IF($I40="Hito",IF($J40="Completado","◆","◇")," "),"") | P40: =IF(AND($F40<=P$10+6,$G40>=P$10),IF($I40="Hito",IF($J40="Completado","◆","◇")," "),"") | Q40: =IF(AND($F40<=Q$10+6,$G40>=Q$10),IF($I40="Hito",IF($J40="Completado","◆","◇")," "),"") | R40: =IF(AND($F40<=R$10+6,$G40>=R$10),IF($I40="Hito",IF($J40="Completado","◆","◇")," "),"") | ... AB40: =IF(AND($F40<=AB$10+6,$G40>=AB$10),IF($I40="Hito",IF($J40="Completado","◆","◇")," "),"")
...

Sheet Sprints
A1: Sprint | B1: Objetivo | C1: Inicio | D1: Fin | E1: Días | F1: Semanas del curso | G1: Incremento entregado | H1: Pull requests | I1: Estado
A2: Sprint 1 | B2: Infraestructura en la nube | C2: 46290 | D2: 46300 | E2: =D2-C2+1 -> 11 | F2: ="S"&(INT((C2-'Carta Gantt'!$C$3)/7)+1)&" a S"&(INT((D2-'Carta Gantt'!$C$3)/7)+1) -> S7 a S9 | G2: Servidor SOAR-CORE-01 (Contabo) con NetBird, Docker y Wazuh 4.14.8 | H2: — | I2: Completado
A3: Sprint 2 | B3: Núcleo de decisión | C3: 46301 | D3: 46314 | E3: =D3-C3+1 -> 14 | F3: ="S"&(INT((C3-'Carta Gantt'!$C$3)/7)+1)&" a S"&(INT((D3-'Carta Gantt'!$C$3)/7)+1) -> S9 a S11 | G3: Base de auditoría, clasificador con IA local, VALIDATE, EXECUTE, NOTIFY, consola web, respaldo y CI | H3: #1 a #30 | I3: Completado
A4: Sprint 3 | B4: Respuesta, niveles y versión 1.0 | C4: 46315 | D4: 46328 | E4: =D4-C4+1 -> 14 | F4: ="S"&(INT((C4-'Carta Gantt'!$C$3)/7)+1)&" a S"&(INT((D4-'Carta Gantt'!$C$3)/7)+1) -> S11 a S13 | G4: Respuesta activa con reversión, avisos por Telegram, scripts de Windows, prueba integral E1 a E7 y versión 1.0.0 | H4: #31 a #38 y #75 a #84 | I4: En curso
A5: Sprint 4 | B5: Estabilización y estudio cruzado | C5: 46329 | D5: 46342 | E5: =D5-C5+1 -> 14 | F5: ="S"&(INT((C5-'Carta Gantt'!$C$3)/7)+1)&" a S"&(INT((D5-'Carta Gantt'!$C$3)/7)+1) -> S13 a S15 | G5: Prueba con un encargado de TI, corrección de errores, informe en limpio y primer simulacro | H5: — | I5: Planificado
A6: Sprint 5 | B6: Ensayos y congelamiento | C6: 46343 | D6: 46355 | E6: =D6-C6+1 -> 13 | F6: ="S"&(INT((C6-'Carta Gantt'!$C$3)/7)+1)&" a S"&(INT((D6-'Carta Gantt'!$C$3)/7)+1) -> S15 a S16 | G6: Ensayo con el profesor guía, ensayos cronometrados y sistema congelado para la defensa | H6: — | I6: Planificado
A8: Cada sprint dura dos semanas y termina con un incremento probado e integrado (pull request con revisión cruzada y pruebas automáticas en verde). Antes del Sprint 1, la Fase 1 definió el proyecto y validó el diseño con un prototipo en laboratorio local.

Sheet Hitos
A1: Fecha | B1: Semana | C1: Fase | D1: Hito | E1: Responsable | F1: Estado | G1: Evidencia
A2: 46244 | B2: ="S"&(INT((A2-'Carta Gantt'!$C$3)/7)+1) -> S1 | C2: Fase 1 | D2: Kick-off con el profesor guía | E2: Equipo | F2: Completado | G2: Inicio del proyecto
A3: 46255 | B3: ="S"&(INT((A3-'Carta Gantt'!$C$3)/7)+1) -> S2 | C3: Fase 1 | D3: Primera presentación del proyecto | E3: Equipo | F3: Completado | G3: Presentación «Proyecto KRONOS»
A4: 46268 | B4: ="S"&(INT((A4-'Carta Gantt'!$C$3)/7)+1) -> S4 | C4: Fase 1 | D4: Presentación de la Fase 1 | E4: Equipo | F4: Completado | G4: Guion de 10 minutos
A5: 46290 | B5: ="S"&(INT((A5-'Carta Gantt'!$C$3)/7)+1) -> S7 | C5: Fase 2 | D5: Replanteamiento como servicio en la nube | E5: Equipo | F5: Completado | G5: Inicio del Sprint 1
A6: 46311 | B6: ="S"&(INT((A6-'Carta Gantt'!$C$3)/7)+1) -> S10 | C6: Fase 2 | D6: Entrega de documentos | E6: Equipo | F6: Completado | G6: 31 documentos entregados
A7: 46315 | B7: ="S"&(INT((A7-'Carta Gantt'!$C$3)/7)+1) -> S11 | C7: Fase 2 | D7: Primer ticket de punta a punta con alertas reales | E7: Equipo | F7: Completado | G7: Ticket 20
A8: 46316 | B8: ="S"&(INT((A8-'Carta Gantt'!$C$3)/7)+1) -> S11 | C8: Fase 2 | D8: Punto de encuentro 1 (decisiones D-44 a D-56) | E8: Equipo | F8: Completado | G8: Acta del 21-10
A9: 46321 | B9: ="S"&(INT((A9-'Carta Gantt'!$C$3)/7)+1) -> S12 | C9: Fase 2 | D9: Replanteamiento para PyMEs y arranque de la semana de cierre | E9: Equipo | F9: Completado | G9: Plan del 26-10
A10: 46324 | B10: ="S"&(INT((A10-'Carta Gantt'!$C$3)/7)+1) -> S12 | C10: Fase 2 | D10: Prueba integral, escenarios E1 a E7 (punto de encuentro 2) | E10: Equipo | F10: Planificado | G10: Issue #40
A11: 46326 | B11: ="S"&(INT((A11-'Carta Gantt'!$C$3)/7)+1) -> S12 | C11: Fase 2 | D11: Versión 1.0.0: etiqueta en main y notas de la versión | E11: Rodrigo | F11: Planificado | G11: Issue #62

Sheet Notas y fuentes
A1: Cómo se lee
A2: Cada fila es una actividad; las celdas de color marcan las semanas en que ocurre. El color dice su estado (verde: completado; naranja: en curso; azul: planificado) y ◆ marca un hito cumplido (◇, uno por cumplir). La columna roja es la semana de la fecha de corte.
A3: Las semanas S1 a S18 siguen el formato de la carta Gantt de la Guía de definición del proyecto APT (Duoc): Fase 1 en S1 a S4, Fase 2 en S5 a S16 y Fase 3 en S17 y S18. La semana 1 empieza el lunes del kick-off (10-08-2026).
A4: Para actualizarla: cambiar la fecha de corte (C4 de la hoja Carta Gantt) y el estado o las fechas de cada actividad (columnas F, G y J). Las barras, la fila de sprints y el avance se recalculan solos.
A5: Supuestos
A6: Las fechas del prototipo en laboratorio local (agosto y septiembre) y de los documentos de avance de la Fase 2 son aproximadas: el repositorio actual se creó el 06-10 y esas actividades no tienen commits.
A7: Sprint 4, Sprint 5 y Fase 3 son la planificación del plan del 26-10 (sección 10). La fecha exacta de la defensa está por confirmar; se usa la primera semana de diciembre. El contrato del servidor vence el 10-12.
A8: Las fechas de las actividades del repositorio salen del historial de git: la fecha en que se mezcló cada pull request.
A9: Fuentes
A10: Repositorio soarai2026/kronos-ai: historial de git y pull requests #1 a #84; Fase 2/Avances/CHANGELOG.md.
A11: Fase 2/Avances/docs/registro: plan del 26-10 (secciones 7 y 10), tareas del 21 y 26-10, acta del 21-10, registros de trabajo del 15 al 21-10 y registro de decisiones.
A12: Fase 1 y Fase 2 (README y documentación grupal): Guía de definición del proyecto APT, Formativa Fase 1, Guía de desarrollo del proyecto y Formativa de avance de la Fase 2.
